[INFO     20.20.2023 21:37:31 at           <module>]: Запускаю бота...
[INFO     20.20.2023 21:37:31 at           <module>]: Загрузился успешно!
[INFO     20.20.2023 21:37:34 at           _welcome]: Bot: Dalmee_bot [@Dalmee_bot]
[WARNING  20.20.2023 21:37:34 at           _skip_updates]: Updates were skipped successfully.
[INFO     20.20.2023 21:37:34 at           start_polling]: Start polling.
[INFO     20.20.2023 22:29:58 at           <module>]: Запускаю бота...
[INFO     20.20.2023 22:29:58 at           <module>]: Загрузился успешно!
[INFO     20.20.2023 22:29:59 at           _welcome]: Bot: Dalmee_bot [@Dalmee_bot]
[WARNING  20.20.2023 22:29:59 at           _skip_updates]: Updates were skipped successfully.
[INFO     20.20.2023 22:29:59 at           start_polling]: Start polling.
[ERROR    20.20.2023 22:30:01 at           default_exception_handler]: Task exception was never retrieved
future: <Task finished name='Task-14' coro=<Dispatcher._process_polling_updates() done, defined at C:\Users\Admin\AppData\Local\Programs\Python\Python310\lib\site-packages\aiogram\dispatcher\dispatcher.py:407> exception=TypeError("videos_command_videoChoice() missing 1 required positional argument: 'call'")>
Traceback (most recent call last):
  File "C:\Users\Admin\AppData\Local\Programs\Python\Python310\lib\site-packages\aiogram\dispatcher\dispatcher.py", line 415, in _process_polling_updates
    for responses in itertools.chain.from_iterable(await self.process_updates(updates, fast)):
  File "C:\Users\Admin\AppData\Local\Programs\Python\Python310\lib\site-packages\aiogram\dispatcher\dispatcher.py", line 235, in process_updates
    return await asyncio.gather(*tasks)
  File "C:\Users\Admin\AppData\Local\Programs\Python\Python310\lib\site-packages\aiogram\dispatcher\handler.py", line 116, in notify
    response = await handler_obj.handler(*args, **partial_data)
  File "C:\Users\Admin\AppData\Local\Programs\Python\Python310\lib\site-packages\aiogram\dispatcher\dispatcher.py", line 283, in process_update
    return await self.callback_query_handlers.notify(update.callback_query)
  File "C:\Users\Admin\AppData\Local\Programs\Python\Python310\lib\site-packages\aiogram\dispatcher\handler.py", line 116, in notify
    response = await handler_obj.handler(*args, **partial_data)
TypeError: videos_command_videoChoice() missing 1 required positional argument: 'call'
[INFO     20.20.2023 22:32:14 at           <module>]: Запускаю бота...
[INFO     20.20.2023 22:32:14 at           <module>]: Загрузился успешно!
[INFO     20.20.2023 22:32:14 at           _welcome]: Bot: Dalmee_bot [@Dalmee_bot]
[WARNING  20.20.2023 22:32:14 at           _skip_updates]: Updates were skipped successfully.
[INFO     20.20.2023 22:32:14 at           start_polling]: Start polling.
[INFO     21.21.2023 16:19:54 at           <module>]: Запускаю бота...
[INFO     21.21.2023 16:19:54 at           <module>]: Загрузился успешно!
[INFO     21.21.2023 16:19:54 at           _welcome]: Bot: Dalmee_bot [@Dalmee_bot]
[WARNING  21.21.2023 16:19:54 at           _skip_updates]: Updates were skipped successfully.
[INFO     21.21.2023 16:19:54 at           start_polling]: Start polling.
[ERROR    21.21.2023 16:41:32 at           start_polling]: Cause exception while getting updates.
Traceback (most recent call last):
  File "C:\Users\Admin\AppData\Local\Programs\Python\Python310\lib\site-packages\aiogram\dispatcher\dispatcher.py", line 381, in start_polling
    updates = await self.bot.get_updates(
  File "C:\Users\Admin\AppData\Local\Programs\Python\Python310\lib\site-packages\aiogram\bot\bot.py", line 110, in get_updates
    result = await self.request(api.Methods.GET_UPDATES, payload)
  File "C:\Users\Admin\AppData\Local\Programs\Python\Python310\lib\site-packages\aiogram\bot\base.py", line 236, in request
    return await api.make_request(await self.get_session(), self.server, self.__token, method, data, files,
  File "C:\Users\Admin\AppData\Local\Programs\Python\Python310\lib\site-packages\aiogram\bot\api.py", line 140, in make_request
    return check_result(method, response.content_type, response.status, await response.text())
  File "C:\Users\Admin\AppData\Local\Programs\Python\Python310\lib\site-packages\aiogram\bot\api.py", line 111, in check_result
    raise exceptions.RetryAfter(parameters.retry_after)
aiogram.utils.exceptions.RetryAfter: Flood control exceeded. Retry in 5 seconds.
[INFO     21.21.2023 16:52:43 at           <module>]: Запускаю бота...
[INFO     21.21.2023 16:52:43 at           <module>]: Загрузился успешно!
[INFO     21.21.2023 16:52:44 at           _welcome]: Bot: Dalmee_bot [@Dalmee_bot]
[WARNING  21.21.2023 16:52:44 at           _skip_updates]: Updates were skipped successfully.
[INFO     21.21.2023 16:52:44 at           start_polling]: Start polling.
[ERROR    21.21.2023 16:52:48 at           default_exception_handler]: Task exception was never retrieved
future: <Task finished name='Task-9' coro=<Dispatcher._process_polling_updates() done, defined at C:\Users\Admin\AppData\Local\Programs\Python\Python310\lib\site-packages\aiogram\dispatcher\dispatcher.py:407> exception=TypeError("playlist_keyboard_creating() missing 1 required positional argument: 'playlist_id'")>
Traceback (most recent call last):
  File "C:\Users\Admin\AppData\Local\Programs\Python\Python310\lib\site-packages\aiogram\dispatcher\dispatcher.py", line 415, in _process_polling_updates
    for responses in itertools.chain.from_iterable(await self.process_updates(updates, fast)):
  File "C:\Users\Admin\AppData\Local\Programs\Python\Python310\lib\site-packages\aiogram\dispatcher\dispatcher.py", line 235, in process_updates
    return await asyncio.gather(*tasks)
  File "C:\Users\Admin\AppData\Local\Programs\Python\Python310\lib\site-packages\aiogram\dispatcher\handler.py", line 116, in notify
    response = await handler_obj.handler(*args, **partial_data)
  File "C:\Users\Admin\AppData\Local\Programs\Python\Python310\lib\site-packages\aiogram\dispatcher\dispatcher.py", line 256, in process_update
    return await self.message_handlers.notify(update.message)
  File "C:\Users\Admin\AppData\Local\Programs\Python\Python310\lib\site-packages\aiogram\dispatcher\handler.py", line 116, in notify
    response = await handler_obj.handler(*args, **partial_data)
  File "e:\TelegramBot_For_Dalmee\TelegramBot.py", line 104, in videos_command_playlistChoice
    await msg.answer("Выбери интересующий тебя плейлист:", reply_markup=await playlist_keyboard_creating())
TypeError: playlist_keyboard_creating() missing 1 required positional argument: 'playlist_id'
[INFO     21.21.2023 16:53:10 at           <module>]: Запускаю бота...
[INFO     21.21.2023 16:53:10 at           <module>]: Загрузился успешно!
[INFO     21.21.2023 16:53:11 at           _welcome]: Bot: Dalmee_bot [@Dalmee_bot]
[WARNING  21.21.2023 16:53:11 at           _skip_updates]: Updates were skipped successfully.
[INFO     21.21.2023 16:53:11 at           start_polling]: Start polling.
[ERROR    21.21.2023 16:53:17 at           default_exception_handler]: Task exception was never retrieved
future: <Task finished name='Task-14' coro=<Dispatcher._process_polling_updates() done, defined at C:\Users\Admin\AppData\Local\Programs\Python\Python310\lib\site-packages\aiogram\dispatcher\dispatcher.py:407> exception=TypeError('playlist_keyboard_creating() takes 0 positional arguments but 1 was given')>
Traceback (most recent call last):
  File "C:\Users\Admin\AppData\Local\Programs\Python\Python310\lib\site-packages\aiogram\dispatcher\dispatcher.py", line 415, in _process_polling_updates
    for responses in itertools.chain.from_iterable(await self.process_updates(updates, fast)):
  File "C:\Users\Admin\AppData\Local\Programs\Python\Python310\lib\site-packages\aiogram\dispatcher\dispatcher.py", line 235, in process_updates
    return await asyncio.gather(*tasks)
  File "C:\Users\Admin\AppData\Local\Programs\Python\Python310\lib\site-packages\aiogram\dispatcher\handler.py", line 116, in notify
    response = await handler_obj.handler(*args, **partial_data)
  File "C:\Users\Admin\AppData\Local\Programs\Python\Python310\lib\site-packages\aiogram\dispatcher\dispatcher.py", line 283, in process_update
    return await self.callback_query_handlers.notify(update.callback_query)
  File "C:\Users\Admin\AppData\Local\Programs\Python\Python310\lib\site-packages\aiogram\dispatcher\handler.py", line 116, in notify
    response = await handler_obj.handler(*args, **partial_data)
  File "e:\TelegramBot_For_Dalmee\TelegramBot.py", line 111, in videos_command_videoChoice
    await call.message.edit_text("Выбери интересующее тебя видео:", reply_markup=await playlist_keyboard_creating(call.data[9:]))
TypeError: playlist_keyboard_creating() takes 0 positional arguments but 1 was given
[INFO     21.21.2023 16:53:46 at           <module>]: Запускаю бота...
[INFO     21.21.2023 16:53:46 at           <module>]: Загрузился успешно!
[INFO     21.21.2023 16:53:46 at           _welcome]: Bot: Dalmee_bot [@Dalmee_bot]
[WARNING  21.21.2023 16:53:46 at           _skip_updates]: Updates were skipped successfully.
[INFO     21.21.2023 16:53:46 at           start_polling]: Start polling.
[ERROR    21.21.2023 16:53:50 at           default_exception_handler]: Task exception was never retrieved
future: <Task finished name='Task-9' coro=<Dispatcher._process_polling_updates() done, defined at C:\Users\Admin\AppData\Local\Programs\Python\Python310\lib\site-packages\aiogram\dispatcher\dispatcher.py:407> exception=TypeError('playlist_keyboard_creating() takes 0 positional arguments but 1 was given')>
Traceback (most recent call last):
  File "C:\Users\Admin\AppData\Local\Programs\Python\Python310\lib\site-packages\aiogram\dispatcher\dispatcher.py", line 415, in _process_polling_updates
    for responses in itertools.chain.from_iterable(await self.process_updates(updates, fast)):
  File "C:\Users\Admin\AppData\Local\Programs\Python\Python310\lib\site-packages\aiogram\dispatcher\dispatcher.py", line 235, in process_updates
    return await asyncio.gather(*tasks)
  File "C:\Users\Admin\AppData\Local\Programs\Python\Python310\lib\site-packages\aiogram\dispatcher\handler.py", line 116, in notify
    response = await handler_obj.handler(*args, **partial_data)
  File "C:\Users\Admin\AppData\Local\Programs\Python\Python310\lib\site-packages\aiogram\dispatcher\dispatcher.py", line 283, in process_update
    return await self.callback_query_handlers.notify(update.callback_query)
  File "C:\Users\Admin\AppData\Local\Programs\Python\Python310\lib\site-packages\aiogram\dispatcher\handler.py", line 116, in notify
    response = await handler_obj.handler(*args, **partial_data)
  File "e:\TelegramBot_For_Dalmee\TelegramBot.py", line 111, in videos_command_videoChoice
    await call.message.edit_text("Выбери интересующее тебя видео:", reply_markup=await playlist_keyboard_creating(call.data[9:]))
TypeError: playlist_keyboard_creating() takes 0 positional arguments but 1 was given
[INFO     21.21.2023 16:54:13 at           <module>]: Запускаю бота...
[INFO     21.21.2023 16:54:13 at           <module>]: Загрузился успешно!
[INFO     21.21.2023 16:54:13 at           _welcome]: Bot: Dalmee_bot [@Dalmee_bot]
[WARNING  21.21.2023 16:54:13 at           _skip_updates]: Updates were skipped successfully.
[INFO     21.21.2023 16:54:13 at           start_polling]: Start polling.
[INFO     21.21.2023 16:57:07 at           <module>]: Запускаю бота...
[INFO     21.21.2023 16:57:07 at           <module>]: Загрузился успешно!
[INFO     21.21.2023 16:57:07 at           _welcome]: Bot: Dalmee_bot [@Dalmee_bot]
[WARNING  21.21.2023 16:57:07 at           _skip_updates]: Updates were skipped successfully.
[INFO     21.21.2023 16:57:07 at           start_polling]: Start polling.
[INFO     21.21.2023 17:16:16 at           <module>]: Запускаю бота...
[INFO     21.21.2023 17:16:16 at           <module>]: Загрузился успешно!
[INFO     21.21.2023 17:16:16 at           _welcome]: Bot: Dalmee_bot [@Dalmee_bot]
[WARNING  21.21.2023 17:16:16 at           _skip_updates]: Updates were skipped successfully.
[INFO     21.21.2023 17:16:16 at           start_polling]: Start polling.
[ERROR    21.21.2023 17:16:17 at           default_exception_handler]: Task exception was never retrieved
future: <Task finished name='Task-9' coro=<Dispatcher._process_polling_updates() done, defined at C:\Users\Admin\AppData\Local\Programs\Python\Python310\lib\site-packages\aiogram\dispatcher\dispatcher.py:407> exception=<HttpError 404 when requesting https://youtube.googleapis.com/youtube/v3/playlists?part=snippet&channelId=DalmeeYT&maxResults=50&key=AIzaSyAskIzatMxeTKd-Y1jcyViO4XZcoczXvfk&alt=json returned "Channel not found.". Details: "[{'message': 'Channel not found.', 'domain': 'youtube.playlist', 'reason': 'channelNotFound', 'location': 'channelId', 'locationType': 'parameter'}]">>
Traceback (most recent call last):
  File "C:\Users\Admin\AppData\Local\Programs\Python\Python310\lib\site-packages\aiogram\dispatcher\dispatcher.py", line 415, in _process_polling_updates
    for responses in itertools.chain.from_iterable(await self.process_updates(updates, fast)):
  File "C:\Users\Admin\AppData\Local\Programs\Python\Python310\lib\site-packages\aiogram\dispatcher\dispatcher.py", line 235, in process_updates
    return await asyncio.gather(*tasks)
  File "C:\Users\Admin\AppData\Local\Programs\Python\Python310\lib\site-packages\aiogram\dispatcher\handler.py", line 116, in notify
    response = await handler_obj.handler(*args, **partial_data)
  File "C:\Users\Admin\AppData\Local\Programs\Python\Python310\lib\site-packages\aiogram\dispatcher\dispatcher.py", line 256, in process_update
    return await self.message_handlers.notify(update.message)
  File "C:\Users\Admin\AppData\Local\Programs\Python\Python310\lib\site-packages\aiogram\dispatcher\handler.py", line 116, in notify
    response = await handler_obj.handler(*args, **partial_data)
  File "e:\TelegramBot_For_Dalmee\TelegramBot.py", line 109, in videos_command_playlistChoice
    await msg.answer("Выбери интересующий тебя плейлист:", reply_markup=await playlist_keyboard_creating())
  File "e:\TelegramBot_For_Dalmee\TelegramBot.py", line 24, in playlist_keyboard_creating
    response = request.execute()
  File "C:\Users\Admin\AppData\Local\Programs\Python\Python310\lib\site-packages\googleapiclient\_helpers.py", line 130, in positional_wrapper
    return wrapped(*args, **kwargs)
  File "C:\Users\Admin\AppData\Local\Programs\Python\Python310\lib\site-packages\googleapiclient\http.py", line 938, in execute
    raise HttpError(resp, content, uri=self.uri)
googleapiclient.errors.HttpError: <HttpError 404 when requesting https://youtube.googleapis.com/youtube/v3/playlists?part=snippet&channelId=DalmeeYT&maxResults=50&key=AIzaSyAskIzatMxeTKd-Y1jcyViO4XZcoczXvfk&alt=json returned "Channel not found.". Details: "[{'message': 'Channel not found.', 'domain': 'youtube.playlist', 'reason': 'channelNotFound', 'location': 'channelId', 'locationType': 'parameter'}]">
